<Type Name="TargetInvocationException" FullName="System.Reflection.TargetInvocationException">
  <Metadata><Meta Name="ms.openlocfilehash" Value="c6b13774ff83b6e222e12683a773b9a4e03e8b2d" /><Meta Name="ms.sourcegitcommit" Value="055a4a82a0b08bfbdc21bd1347fb71f7fe2c099e" /><Meta Name="ms.translationtype" Value="MT" /><Meta Name="ms.contentlocale" Value="ru-RU" /><Meta Name="ms.lasthandoff" Value="08/15/2019" /><Meta Name="ms.locfileid" Value="69067092" /></Metadata><TypeSignature Language="C#" Value="public sealed class TargetInvocationException : ApplicationException" />
  <TypeSignature Language="ILAsm" Value=".class public auto ansi serializable sealed beforefieldinit TargetInvocationException extends System.ApplicationException" />
  <TypeSignature Language="DocId" Value="T:System.Reflection.TargetInvocationException" />
  <TypeSignature Language="VB.NET" Value="Public NotInheritable Class TargetInvocationException&#xA;Inherits ApplicationException" />
  <TypeSignature Language="C++ CLI" Value="public ref class TargetInvocationException sealed : ApplicationException" />
  <TypeSignature Language="F#" Value="type TargetInvocationException = class&#xA;    inherit ApplicationException" />
  <AssemblyInfo>
    <AssemblyName>System.Reflection</AssemblyName>
    <AssemblyVersion>4.0.0.0</AssemblyVersion>
    <AssemblyVersion>4.0.10.0</AssemblyVersion>
    <AssemblyVersion>4.1.0.0</AssemblyVersion>
  </AssemblyInfo>
  <AssemblyInfo>
    <AssemblyName>mscorlib</AssemblyName>
    <AssemblyVersion>1.0.5000.0</AssemblyVersion>
    <AssemblyVersion>2.0.0.0</AssemblyVersion>
    <AssemblyVersion>2.0.5.0</AssemblyVersion>
    <AssemblyVersion>4.0.0.0</AssemblyVersion>
  </AssemblyInfo>
  <AssemblyInfo>
    <AssemblyName>netstandard</AssemblyName>
    <AssemblyVersion>2.0.0.0</AssemblyVersion>
    <AssemblyVersion>2.1.0.0</AssemblyVersion>
  </AssemblyInfo>
  <AssemblyInfo>
    <AssemblyName>System.Runtime</AssemblyName>
    <AssemblyVersion>4.2.0.0</AssemblyVersion>
    <AssemblyVersion>4.2.1.0</AssemblyVersion>
  </AssemblyInfo>
  <Base>
    <BaseTypeName>System.Exception</BaseTypeName>
    <BaseTypeName FrameworkAlternate="netframework-4.5">System.ApplicationException</BaseTypeName>
  </Base>
  <Interfaces />
  <Attributes>
    <Attribute FrameworkAlternate="netframework-2.0;netframework-3.0;netframework-3.5;netframework-4.0;netframework-4.5;netframework-4.5.1;netframework-4.5.2;netframework-4.6;netframework-4.6.1;netframework-4.6.2;netframework-4.7;netframework-4.7.1;netframework-4.7.2;xamarinandroid-7.1;xamarinios-10.8;xamarinmac-3.0;netframework-4.8">
      <AttributeName>System.Runtime.InteropServices.ComVisible(true)</AttributeName>
    </Attribute>
    <Attribute FrameworkAlternate="netframework-1.1;netframework-2.0;netframework-3.0;netframework-3.5;netframework-4.0;netframework-4.5;netframework-4.5.1;netframework-4.5.2;netframework-4.6;netframework-4.6.1;netframework-4.6.2;netframework-4.7;netframework-4.7.1;netframework-4.7.2;netframework-4.8;xamarinandroid-7.1;xamarinios-10.8;xamarinmac-3.0">
      <AttributeName>System.Serializable</AttributeName>
    </Attribute>
  </Attributes>
  <Docs>
    <summary><span data-ttu-id="f8abe-101">Исключение выдается методами, вызываемыми средствами отражения.</span><span class="sxs-lookup"><span data-stu-id="f8abe-101">The exception that is thrown by methods invoked through reflection.</span></span> <span data-ttu-id="f8abe-102">Этот класс не наследуется.</span><span class="sxs-lookup"><span data-stu-id="f8abe-102">This class cannot be inherited.</span></span></summary>
    <remarks>
      <format type="text/markdown"><![CDATA[  
  
## Remarks  
 <span data-ttu-id="f8abe-103">Для получения дополнительной информации см. <xref:System.Reflection.MethodBase.Invoke%2A>.</span><span class="sxs-lookup"><span data-stu-id="f8abe-103">For more information, see <xref:System.Reflection.MethodBase.Invoke%2A>.</span></span>  
  
 <span data-ttu-id="f8abe-104">`TargetInvocationException`использует значение HRESULT COR_E_TARGETINVOCATION со значением 0x80131604.</span><span class="sxs-lookup"><span data-stu-id="f8abe-104">`TargetInvocationException` uses the HRESULT COR_E_TARGETINVOCATION which has the value 0x80131604.</span></span>  
  
 <span data-ttu-id="f8abe-105">При создании `TargetInvocationException` передается ссылка на исключение, созданное методом, вызванным через отражение.</span><span class="sxs-lookup"><span data-stu-id="f8abe-105">When created, the `TargetInvocationException` is passed a reference to the exception thrown by the method invoked through reflection.</span></span> <span data-ttu-id="f8abe-106"><xref:System.Exception.InnerException%2A> Свойство содержит базовое исключение.</span><span class="sxs-lookup"><span data-stu-id="f8abe-106">The <xref:System.Exception.InnerException%2A> property holds the underlying exception.</span></span>  
  
 ]]></format>
    </remarks>
    <altmember cref="P:System.Exception.InnerException" />
    <altmember cref="T:System.Exception" />
    <related type="Article" href="~/docs/standard/exceptions/index.md"><span data-ttu-id="f8abe-107">Обработка и создание исключений в .NET</span><span class="sxs-lookup"><span data-stu-id="f8abe-107">Handling and throwing exceptions in .NET</span></span></related>
  </Docs>
  <Members>
    <MemberGroup MemberName=".ctor">
      <AssemblyInfo>
        <AssemblyName>System.Reflection</AssemblyName>
        <AssemblyVersion>4.0.0.0</AssemblyVersion>
        <AssemblyVersion>4.0.10.0</AssemblyVersion>
        <AssemblyVersion>4.1.0.0</AssemblyVersion>
      </AssemblyInfo>
      <Docs>
        <summary><span data-ttu-id="f8abe-108">Инициализирует новый экземпляр класса <see cref="T:System.Reflection.TargetInvocationException" />.</span><span class="sxs-lookup"><span data-stu-id="f8abe-108">Initializes a new instance of the <see cref="T:System.Reflection.TargetInvocationException" /> class.</span></span></summary>
      </Docs>
    </MemberGroup>
    <Member MemberName=".ctor">
      <MemberSignature Language="C#" Value="public TargetInvocationException (Exception inner);" />
      <MemberSignature Language="ILAsm" Value=".method public hidebysig specialname rtspecialname instance void .ctor(class System.Exception inner) cil managed" />
      <MemberSignature Language="DocId" Value="M:System.Reflection.TargetInvocationException.#ctor(System.Exception)" />
      <MemberSignature Language="VB.NET" Value="Public Sub New (inner As Exception)" />
      <MemberSignature Language="C++ CLI" Value="public:&#xA; TargetInvocationException(Exception ^ inner);" />
      <MemberSignature Language="F#" Value="new System.Reflection.TargetInvocationException : Exception -&gt; System.Reflection.TargetInvocationException" Usage="new System.Reflection.TargetInvocationException inner" />
      <MemberType>Constructor</MemberType>
      <AssemblyInfo>
        <AssemblyName>System.Reflection</AssemblyName>
        <AssemblyVersion>4.0.0.0</AssemblyVersion>
        <AssemblyVersion>4.0.10.0</AssemblyVersion>
        <AssemblyVersion>4.1.0.0</AssemblyVersion>
      </AssemblyInfo>
      <AssemblyInfo>
        <AssemblyName>mscorlib</AssemblyName>
        <AssemblyVersion>1.0.5000.0</AssemblyVersion>
        <AssemblyVersion>2.0.0.0</AssemblyVersion>
        <AssemblyVersion>2.0.5.0</AssemblyVersion>
        <AssemblyVersion>4.0.0.0</AssemblyVersion>
      </AssemblyInfo>
      <AssemblyInfo>
        <AssemblyName>netstandard</AssemblyName>
        <AssemblyVersion>2.0.0.0</AssemblyVersion>
        <AssemblyVersion>2.1.0.0</AssemblyVersion>
      </AssemblyInfo>
      <AssemblyInfo>
        <AssemblyName>System.Runtime</AssemblyName>
        <AssemblyVersion>4.2.0.0</AssemblyVersion>
        <AssemblyVersion>4.2.1.0</AssemblyVersion>
      </AssemblyInfo>
      <Parameters>
        <Parameter Name="inner" Type="System.Exception" />
      </Parameters>
      <Docs>
        <param name="inner"><span data-ttu-id="f8abe-109">Исключение, которое является причиной текущего исключения.</span><span class="sxs-lookup"><span data-stu-id="f8abe-109">The exception that is the cause of the current exception.</span></span> <span data-ttu-id="f8abe-110">Если значение параметра <paramref name="inner" /> не равно <see langword="null" />, текущее исключение сгенерировано в блоке <see langword="catch" />, обрабатывающем внутреннее исключение.</span><span class="sxs-lookup"><span data-stu-id="f8abe-110">If the <paramref name="inner" /> parameter is not <see langword="null" />, the current exception is raised in a <see langword="catch" /> block that handles the inner exception.</span></span></param>
        <summary><span data-ttu-id="f8abe-111">Инициализирует новый экземпляр класса <see cref="T:System.Reflection.TargetInvocationException" /> со ссылкой на внутреннее исключение, которое является причиной данного исключения.</span><span class="sxs-lookup"><span data-stu-id="f8abe-111">Initializes a new instance of the <see cref="T:System.Reflection.TargetInvocationException" /> class with a reference to the inner exception that is the cause of this exception.</span></span></summary>
        <remarks>
          <format type="text/markdown"><![CDATA[  
  
## Remarks  
 <span data-ttu-id="f8abe-112">Исключение, созданное как прямой результат предыдущего исключения, должно содержать в свойстве <xref:System.Exception.InnerException%2A> ссылку на предыдущее исключение.</span><span class="sxs-lookup"><span data-stu-id="f8abe-112">An exception that is thrown as a direct result of a previous exception should include a reference to the previous exception in the <xref:System.Exception.InnerException%2A> property.</span></span> <span data-ttu-id="f8abe-113">Свойство <xref:System.Exception.InnerException%2A> возвращает значение, переданное конструктору, или значение `null`, если свойство <xref:System.Exception.InnerException%2A> не передает конструктору значение внутреннего исключения.</span><span class="sxs-lookup"><span data-stu-id="f8abe-113">The <xref:System.Exception.InnerException%2A> property returns the same value that is passed into the constructor, or `null` if the <xref:System.Exception.InnerException%2A> property does not supply the inner exception value to the constructor.</span></span>  
  
 <span data-ttu-id="f8abe-114">В следующей таблице представлены исходные значения свойств экземпляра класса <xref:System.Reflection.TargetInvocationException>.</span><span class="sxs-lookup"><span data-stu-id="f8abe-114">The following table shows the initial property values for an instance of <xref:System.Reflection.TargetInvocationException>.</span></span>  
  
|<span data-ttu-id="f8abe-115">Свойство.</span><span class="sxs-lookup"><span data-stu-id="f8abe-115">Property</span></span>|<span data-ttu-id="f8abe-116">Значение</span><span class="sxs-lookup"><span data-stu-id="f8abe-116">Value</span></span>|  
|--------------|-----------|  
|<xref:System.Exception.InnerException%2A>|<span data-ttu-id="f8abe-117">Ссылка на внутреннее исключение.</span><span class="sxs-lookup"><span data-stu-id="f8abe-117">The inner exception reference.</span></span>|  
|<xref:System.Exception.Message%2A>|<span data-ttu-id="f8abe-118">Строка сообщения об ошибке.</span><span class="sxs-lookup"><span data-stu-id="f8abe-118">The error message string.</span></span>|  
  
 ]]></format>
        </remarks>
        <altmember cref="T:System.Exception" />
        <related type="Article" href="~/docs/standard/exceptions/index.md"><span data-ttu-id="f8abe-119">Обработка и создание исключений в .NET</span><span class="sxs-lookup"><span data-stu-id="f8abe-119">Handling and throwing exceptions in .NET</span></span></related>
      </Docs>
    </Member>
    <Member MemberName=".ctor">
      <MemberSignature Language="C#" Value="public TargetInvocationException (string message, Exception inner);" />
      <MemberSignature Language="ILAsm" Value=".method public hidebysig specialname rtspecialname instance void .ctor(string message, class System.Exception inner) cil managed" />
      <MemberSignature Language="DocId" Value="M:System.Reflection.TargetInvocationException.#ctor(System.String,System.Exception)" />
      <MemberSignature Language="VB.NET" Value="Public Sub New (message As String, inner As Exception)" />
      <MemberSignature Language="C++ CLI" Value="public:&#xA; TargetInvocationException(System::String ^ message, Exception ^ inner);" />
      <MemberSignature Language="F#" Value="new System.Reflection.TargetInvocationException : string * Exception -&gt; System.Reflection.TargetInvocationException" Usage="new System.Reflection.TargetInvocationException (message, inner)" />
      <MemberType>Constructor</MemberType>
      <AssemblyInfo>
        <AssemblyName>System.Reflection</AssemblyName>
        <AssemblyVersion>4.0.0.0</AssemblyVersion>
        <AssemblyVersion>4.0.10.0</AssemblyVersion>
        <AssemblyVersion>4.1.0.0</AssemblyVersion>
      </AssemblyInfo>
      <AssemblyInfo>
        <AssemblyName>mscorlib</AssemblyName>
        <AssemblyVersion>1.0.5000.0</AssemblyVersion>
        <AssemblyVersion>2.0.0.0</AssemblyVersion>
        <AssemblyVersion>2.0.5.0</AssemblyVersion>
        <AssemblyVersion>4.0.0.0</AssemblyVersion>
      </AssemblyInfo>
      <AssemblyInfo>
        <AssemblyName>netstandard</AssemblyName>
        <AssemblyVersion>2.0.0.0</AssemblyVersion>
        <AssemblyVersion>2.1.0.0</AssemblyVersion>
      </AssemblyInfo>
      <AssemblyInfo>
        <AssemblyName>System.Runtime</AssemblyName>
        <AssemblyVersion>4.2.0.0</AssemblyVersion>
        <AssemblyVersion>4.2.1.0</AssemblyVersion>
      </AssemblyInfo>
      <Parameters>
        <Parameter Name="message" Type="System.String" />
        <Parameter Name="inner" Type="System.Exception" />
      </Parameters>
      <Docs>
        <param name="message"><span data-ttu-id="f8abe-120">Сообщение об ошибке, указывающее причину создания исключения.</span><span class="sxs-lookup"><span data-stu-id="f8abe-120">The error message that explains the reason for the exception.</span></span></param>
        <param name="inner"><span data-ttu-id="f8abe-121">Исключение, которое является причиной текущего исключения.</span><span class="sxs-lookup"><span data-stu-id="f8abe-121">The exception that is the cause of the current exception.</span></span> <span data-ttu-id="f8abe-122">Если значение параметра <paramref name="inner" /> не равно <see langword="null" />, текущее исключение сгенерировано в блоке <see langword="catch" />, обрабатывающем внутреннее исключение.</span><span class="sxs-lookup"><span data-stu-id="f8abe-122">If the <paramref name="inner" /> parameter is not <see langword="null" />, the current exception is raised in a <see langword="catch" /> block that handles the inner exception.</span></span></param>
        <summary><span data-ttu-id="f8abe-123">Инициализирует новый экземпляр класса <see cref="T:System.Reflection.TargetInvocationException" /> указанным сообщением об ошибке и ссылкой на внутреннее исключение, вызвавшее данное исключение.</span><span class="sxs-lookup"><span data-stu-id="f8abe-123">Initializes a new instance of the <see cref="T:System.Reflection.TargetInvocationException" /> class with a specified error message and a reference to the inner exception that is the cause of this exception.</span></span></summary>
        <remarks>
          <format type="text/markdown"><![CDATA[  
  
## Remarks  
 <span data-ttu-id="f8abe-124">Исключение, созданное как прямой результат предыдущего исключения, должно содержать в свойстве <xref:System.Exception.InnerException%2A> ссылку на предыдущее исключение.</span><span class="sxs-lookup"><span data-stu-id="f8abe-124">An exception that is thrown as a direct result of a previous exception should include a reference to the previous exception in the <xref:System.Exception.InnerException%2A> property.</span></span> <span data-ttu-id="f8abe-125">Свойство <xref:System.Exception.InnerException%2A> возвращает значение, переданное конструктору, или значение `null`, если свойство <xref:System.Exception.InnerException%2A> не передает конструктору значение внутреннего исключения.</span><span class="sxs-lookup"><span data-stu-id="f8abe-125">The <xref:System.Exception.InnerException%2A> property returns the same value that is passed into the constructor, or `null` if the <xref:System.Exception.InnerException%2A> property does not supply the inner exception value to the constructor.</span></span>  
  
 <span data-ttu-id="f8abe-126">В следующей таблице представлены исходные значения свойств экземпляра класса <xref:System.Reflection.TargetInvocationException>.</span><span class="sxs-lookup"><span data-stu-id="f8abe-126">The following table shows the initial property values for an instance of <xref:System.Reflection.TargetInvocationException>.</span></span>  
  
|<span data-ttu-id="f8abe-127">Свойство.</span><span class="sxs-lookup"><span data-stu-id="f8abe-127">Property</span></span>|<span data-ttu-id="f8abe-128">Значение</span><span class="sxs-lookup"><span data-stu-id="f8abe-128">Value</span></span>|  
|--------------|-----------|  
|<xref:System.Exception.InnerException%2A>|<span data-ttu-id="f8abe-129">Ссылка на внутреннее исключение.</span><span class="sxs-lookup"><span data-stu-id="f8abe-129">The inner exception reference.</span></span>|  
|<xref:System.Exception.Message%2A>|<span data-ttu-id="f8abe-130">Строка сообщения об ошибке.</span><span class="sxs-lookup"><span data-stu-id="f8abe-130">The error message string.</span></span>|  
  
 ]]></format>
        </remarks>
        <altmember cref="T:System.Exception" />
        <related type="Article" href="~/docs/standard/exceptions/index.md"><span data-ttu-id="f8abe-131">Обработка и создание исключений в .NET</span><span class="sxs-lookup"><span data-stu-id="f8abe-131">Handling and throwing exceptions in .NET</span></span></related>
      </Docs>
    </Member>
  </Members>
</Type>
